try {
  //выполнение кода
} catch (error) {
  // этот блок выполняется в случае возникновения ошибок в блоке try
}


const fnWithError = () => {
  throw new Error("Some error");
};
try {
  fnWithError();
} catch (error) {
  console.error(error);
  console.log(error.massage);
}
console.log("Continue");
